[2024-09-30T13:46:41.792+0000] {local_task_job_runner.py:123} INFO - ::group::Pre task execution logs
[2024-09-30T13:46:41.803+0000] {taskinstance.py:2612} INFO - Dependencies all met for dep_context=non-requeueable deps ti=<TaskInstance: mssql_to_postgres_sqlalchemy.load_data_to_staging.incremental_load_from_my_sql manual__2024-09-30T13:42:52.659560+00:00 [queued]>
[2024-09-30T13:46:41.808+0000] {taskinstance.py:2612} INFO - Dependencies all met for dep_context=requeueable deps ti=<TaskInstance: mssql_to_postgres_sqlalchemy.load_data_to_staging.incremental_load_from_my_sql manual__2024-09-30T13:42:52.659560+00:00 [queued]>
[2024-09-30T13:46:41.808+0000] {taskinstance.py:2865} INFO - Starting attempt 4 of 4
[2024-09-30T13:46:41.816+0000] {taskinstance.py:2888} INFO - Executing <Task(PythonOperator): load_data_to_staging.incremental_load_from_my_sql> on 2024-09-30 13:42:52.659560+00:00
[2024-09-30T13:46:41.821+0000] {warnings.py:112} WARNING - /home/***/.local/lib/python3.12/site-packages/***/task/task_runner/standard_task_runner.py:70: DeprecationWarning: This process (pid=88) is multi-threaded, use of fork() may lead to deadlocks in the child.
  pid = os.fork()

[2024-09-30T13:46:41.823+0000] {standard_task_runner.py:72} INFO - Started process 90 to run task
[2024-09-30T13:46:41.823+0000] {standard_task_runner.py:104} INFO - Running: ['***', 'tasks', 'run', 'mssql_to_postgres_sqlalchemy', 'load_data_to_staging.incremental_load_from_my_sql', 'manual__2024-09-30T13:42:52.659560+00:00', '--job-id', '10', '--raw', '--subdir', 'DAGS_FOLDER/load.py', '--cfg-path', '/tmp/tmpa_v5r1en']
[2024-09-30T13:46:41.826+0000] {standard_task_runner.py:105} INFO - Job 10: Subtask load_data_to_staging.incremental_load_from_my_sql
[2024-09-30T13:46:41.861+0000] {task_command.py:467} INFO - Running <TaskInstance: mssql_to_postgres_sqlalchemy.load_data_to_staging.incremental_load_from_my_sql manual__2024-09-30T13:42:52.659560+00:00 [running]> on host 51a7ea638889
[2024-09-30T13:46:41.920+0000] {taskinstance.py:3131} INFO - Exporting env vars: AIRFLOW_CTX_DAG_OWNER='***' AIRFLOW_CTX_DAG_ID='mssql_to_postgres_sqlalchemy' AIRFLOW_CTX_TASK_ID='load_data_to_staging.incremental_load_from_my_sql' AIRFLOW_CTX_EXECUTION_DATE='2024-09-30T13:42:52.659560+00:00' AIRFLOW_CTX_TRY_NUMBER='4' AIRFLOW_CTX_DAG_RUN_ID='manual__2024-09-30T13:42:52.659560+00:00'
[2024-09-30T13:46:41.924+0000] {taskinstance.py:731} INFO - ::endgroup::
[2024-09-30T13:46:41.938+0000] {logging_mixin.py:190} INFO - postgres host: ('postgres', [], ['192.168.112.3'])
[2024-09-30T13:46:41.972+0000] {taskinstance.py:3310} ERROR - Task failed with exception
Traceback (most recent call last):
  File "/home/airflow/.local/lib/python3.12/site-packages/sqlalchemy/engine/base.py", line 1910, in _execute_context
    self.dialect.do_execute(
  File "/home/airflow/.local/lib/python3.12/site-packages/sqlalchemy/engine/default.py", line 736, in do_execute
    cursor.execute(statement, parameters)
psycopg2.errors.UndefinedTable: relation "incremental_data_***" does not exist
LINE 1: ...x(modified), '2000-01-01'::timestamp) as max from incrementa...
                                                             ^


The above exception was the direct cause of the following exception:

Traceback (most recent call last):
  File "/home/airflow/.local/lib/python3.12/site-packages/airflow/models/taskinstance.py", line 767, in _execute_task
    result = _execute_callable(context=context, **execute_callable_kwargs)
             ^^^^^^^^^^^^^^^^^^^^^^^^^^^^^^^^^^^^^^^^^^^^^^^^^^^^^^^^^^^^^
  File "/home/airflow/.local/lib/python3.12/site-packages/airflow/models/taskinstance.py", line 733, in _execute_callable
    return ExecutionCallableRunner(
           ^^^^^^^^^^^^^^^^^^^^^^^^
  File "/home/airflow/.local/lib/python3.12/site-packages/airflow/utils/operator_helpers.py", line 252, in run
    return self.func(*args, **kwargs)
           ^^^^^^^^^^^^^^^^^^^^^^^^^^
  File "/home/airflow/.local/lib/python3.12/site-packages/airflow/models/baseoperator.py", line 406, in wrapper
    return func(self, *args, **kwargs)
           ^^^^^^^^^^^^^^^^^^^^^^^^^^^
  File "/home/airflow/.local/lib/python3.12/site-packages/airflow/operators/python.py", line 238, in execute
    return_value = self.execute_callable()
                   ^^^^^^^^^^^^^^^^^^^^^^^
  File "/home/airflow/.local/lib/python3.12/site-packages/airflow/operators/python.py", line 256, in execute_callable
    return runner.run(*self.op_args, **self.op_kwargs)
           ^^^^^^^^^^^^^^^^^^^^^^^^^^^^^^^^^^^^^^^^^^^
  File "/home/airflow/.local/lib/python3.12/site-packages/airflow/utils/operator_helpers.py", line 252, in run
    return self.func(*args, **kwargs)
           ^^^^^^^^^^^^^^^^^^^^^^^^^^
  File "/opt/airflow/dags/load.py", line 79, in incremental_load_data
    result = connection.execute("select coalesce(max(modified), '2000-01-01'::timestamp) as max from incremental_data_airflow;")
             ^^^^^^^^^^^^^^^^^^^^^^^^^^^^^^^^^^^^^^^^^^^^^^^^^^^^^^^^^^^^^^^^^^^^^^^^^^^^^^^^^^^^^^^^^^^^^^^^^^^^^^^^^^^^^^^^^^^
  File "/home/airflow/.local/lib/python3.12/site-packages/sqlalchemy/engine/base.py", line 1370, in execute
    return self._exec_driver_sql(
           ^^^^^^^^^^^^^^^^^^^^^^
  File "/home/airflow/.local/lib/python3.12/site-packages/sqlalchemy/engine/base.py", line 1674, in _exec_driver_sql
    ret = self._execute_context(
          ^^^^^^^^^^^^^^^^^^^^^^
  File "/home/airflow/.local/lib/python3.12/site-packages/sqlalchemy/engine/base.py", line 1953, in _execute_context
    self._handle_dbapi_exception(
  File "/home/airflow/.local/lib/python3.12/site-packages/sqlalchemy/engine/base.py", line 2134, in _handle_dbapi_exception
    util.raise_(
  File "/home/airflow/.local/lib/python3.12/site-packages/sqlalchemy/util/compat.py", line 211, in raise_
    raise exception
  File "/home/airflow/.local/lib/python3.12/site-packages/sqlalchemy/engine/base.py", line 1910, in _execute_context
    self.dialect.do_execute(
  File "/home/airflow/.local/lib/python3.12/site-packages/sqlalchemy/engine/default.py", line 736, in do_execute
    cursor.execute(statement, parameters)
sqlalchemy.exc.ProgrammingError: (psycopg2.errors.UndefinedTable) relation "incremental_data_***" does not exist
LINE 1: ...x(modified), '2000-01-01'::timestamp) as max from incrementa...
                                                             ^

[SQL: select coalesce(max(modified), '2000-01-01'::timestamp) as max from incremental_data_airflow;]
(Background on this error at: https://sqlalche.me/e/14/f405)
[2024-09-30T13:46:41.983+0000] {taskinstance.py:1225} INFO - Marking task as FAILED. dag_id=mssql_to_postgres_sqlalchemy, task_id=load_data_to_staging.incremental_load_from_my_sql, run_id=manual__2024-09-30T13:42:52.659560+00:00, execution_date=20240930T134252, start_date=20240930T134641, end_date=20240930T134641
[2024-09-30T13:46:41.991+0000] {taskinstance.py:340} INFO - ::group::Post task execution logs
[2024-09-30T13:46:41.992+0000] {standard_task_runner.py:124} ERROR - Failed to execute job 10 for task load_data_to_staging.incremental_load_from_my_sql ((psycopg2.errors.UndefinedTable) relation "incremental_data_***" does not exist
LINE 1: ...x(modified), '2000-01-01'::timestamp) as max from incrementa...
                                                             ^

[SQL: select coalesce(max(modified), '2000-01-01'::timestamp) as max from incremental_data_airflow;]
(Background on this error at: https://sqlalche.me/e/14/f405); 90)
Traceback (most recent call last):
  File "/home/airflow/.local/lib/python3.12/site-packages/sqlalchemy/engine/base.py", line 1910, in _execute_context
    self.dialect.do_execute(
  File "/home/airflow/.local/lib/python3.12/site-packages/sqlalchemy/engine/default.py", line 736, in do_execute
    cursor.execute(statement, parameters)
psycopg2.errors.UndefinedTable: relation "incremental_data_***" does not exist
LINE 1: ...x(modified), '2000-01-01'::timestamp) as max from incrementa...
                                                             ^


The above exception was the direct cause of the following exception:

Traceback (most recent call last):
  File "/home/airflow/.local/lib/python3.12/site-packages/airflow/task/task_runner/standard_task_runner.py", line 117, in _start_by_fork
    ret = args.func(args, dag=self.dag)
          ^^^^^^^^^^^^^^^^^^^^^^^^^^^^^
  File "/home/airflow/.local/lib/python3.12/site-packages/airflow/cli/cli_config.py", line 49, in command
    return func(*args, **kwargs)
           ^^^^^^^^^^^^^^^^^^^^^
  File "/home/airflow/.local/lib/python3.12/site-packages/airflow/utils/cli.py", line 115, in wrapper
    return f(*args, **kwargs)
           ^^^^^^^^^^^^^^^^^^
  File "/home/airflow/.local/lib/python3.12/site-packages/airflow/cli/commands/task_command.py", line 483, in task_run
    task_return_code = _run_task_by_selected_method(args, _dag, ti)
                       ^^^^^^^^^^^^^^^^^^^^^^^^^^^^^^^^^^^^^^^^^^^^
  File "/home/airflow/.local/lib/python3.12/site-packages/airflow/cli/commands/task_command.py", line 256, in _run_task_by_selected_method
    return _run_raw_task(args, ti)
           ^^^^^^^^^^^^^^^^^^^^^^^
  File "/home/airflow/.local/lib/python3.12/site-packages/airflow/cli/commands/task_command.py", line 341, in _run_raw_task
    return ti._run_raw_task(
           ^^^^^^^^^^^^^^^^^
  File "/home/airflow/.local/lib/python3.12/site-packages/airflow/utils/session.py", line 97, in wrapper
    return func(*args, session=session, **kwargs)
           ^^^^^^^^^^^^^^^^^^^^^^^^^^^^^^^^^^^^^^
  File "/home/airflow/.local/lib/python3.12/site-packages/airflow/models/taskinstance.py", line 3004, in _run_raw_task
    return _run_raw_task(
           ^^^^^^^^^^^^^^
  File "/home/airflow/.local/lib/python3.12/site-packages/airflow/models/taskinstance.py", line 273, in _run_raw_task
    TaskInstance._execute_task_with_callbacks(
  File "/home/airflow/.local/lib/python3.12/site-packages/airflow/models/taskinstance.py", line 3158, in _execute_task_with_callbacks
    result = self._execute_task(context, task_orig)
             ^^^^^^^^^^^^^^^^^^^^^^^^^^^^^^^^^^^^^^
  File "/home/airflow/.local/lib/python3.12/site-packages/airflow/models/taskinstance.py", line 3182, in _execute_task
    return _execute_task(self, context, task_orig)
           ^^^^^^^^^^^^^^^^^^^^^^^^^^^^^^^^^^^^^^^
  File "/home/airflow/.local/lib/python3.12/site-packages/airflow/models/taskinstance.py", line 767, in _execute_task
    result = _execute_callable(context=context, **execute_callable_kwargs)
             ^^^^^^^^^^^^^^^^^^^^^^^^^^^^^^^^^^^^^^^^^^^^^^^^^^^^^^^^^^^^^
  File "/home/airflow/.local/lib/python3.12/site-packages/airflow/models/taskinstance.py", line 733, in _execute_callable
    return ExecutionCallableRunner(
           ^^^^^^^^^^^^^^^^^^^^^^^^
  File "/home/airflow/.local/lib/python3.12/site-packages/airflow/utils/operator_helpers.py", line 252, in run
    return self.func(*args, **kwargs)
           ^^^^^^^^^^^^^^^^^^^^^^^^^^
  File "/home/airflow/.local/lib/python3.12/site-packages/airflow/models/baseoperator.py", line 406, in wrapper
    return func(self, *args, **kwargs)
           ^^^^^^^^^^^^^^^^^^^^^^^^^^^
  File "/home/airflow/.local/lib/python3.12/site-packages/airflow/operators/python.py", line 238, in execute
    return_value = self.execute_callable()
                   ^^^^^^^^^^^^^^^^^^^^^^^
  File "/home/airflow/.local/lib/python3.12/site-packages/airflow/operators/python.py", line 256, in execute_callable
    return runner.run(*self.op_args, **self.op_kwargs)
           ^^^^^^^^^^^^^^^^^^^^^^^^^^^^^^^^^^^^^^^^^^^
  File "/home/airflow/.local/lib/python3.12/site-packages/airflow/utils/operator_helpers.py", line 252, in run
    return self.func(*args, **kwargs)
           ^^^^^^^^^^^^^^^^^^^^^^^^^^
  File "/opt/airflow/dags/load.py", line 79, in incremental_load_data
    result = connection.execute("select coalesce(max(modified), '2000-01-01'::timestamp) as max from incremental_data_airflow;")
             ^^^^^^^^^^^^^^^^^^^^^^^^^^^^^^^^^^^^^^^^^^^^^^^^^^^^^^^^^^^^^^^^^^^^^^^^^^^^^^^^^^^^^^^^^^^^^^^^^^^^^^^^^^^^^^^^^^^
  File "/home/airflow/.local/lib/python3.12/site-packages/sqlalchemy/engine/base.py", line 1370, in execute
    return self._exec_driver_sql(
           ^^^^^^^^^^^^^^^^^^^^^^
  File "/home/airflow/.local/lib/python3.12/site-packages/sqlalchemy/engine/base.py", line 1674, in _exec_driver_sql
    ret = self._execute_context(
          ^^^^^^^^^^^^^^^^^^^^^^
  File "/home/airflow/.local/lib/python3.12/site-packages/sqlalchemy/engine/base.py", line 1953, in _execute_context
    self._handle_dbapi_exception(
  File "/home/airflow/.local/lib/python3.12/site-packages/sqlalchemy/engine/base.py", line 2134, in _handle_dbapi_exception
    util.raise_(
  File "/home/airflow/.local/lib/python3.12/site-packages/sqlalchemy/util/compat.py", line 211, in raise_
    raise exception
  File "/home/airflow/.local/lib/python3.12/site-packages/sqlalchemy/engine/base.py", line 1910, in _execute_context
    self.dialect.do_execute(
  File "/home/airflow/.local/lib/python3.12/site-packages/sqlalchemy/engine/default.py", line 736, in do_execute
    cursor.execute(statement, parameters)
sqlalchemy.exc.ProgrammingError: (psycopg2.errors.UndefinedTable) relation "incremental_data_***" does not exist
LINE 1: ...x(modified), '2000-01-01'::timestamp) as max from incrementa...
                                                             ^

[SQL: select coalesce(max(modified), '2000-01-01'::timestamp) as max from incremental_data_airflow;]
(Background on this error at: https://sqlalche.me/e/14/f405)
[2024-09-30T13:46:42.007+0000] {local_task_job_runner.py:266} INFO - Task exited with return code 1
[2024-09-30T13:46:42.026+0000] {taskinstance.py:3900} INFO - 0 downstream tasks scheduled from follow-on schedule check
[2024-09-30T13:46:42.029+0000] {local_task_job_runner.py:245} INFO - ::endgroup::
